Traceback (most recent call last):
  File "d:\github projects\reflectorch\reflectorch\.venv\lib\site-packages\jupyter_cache\executors\utils.py", line 58, in single_nb_execution
    executenb(
  File "d:\github projects\reflectorch\reflectorch\.venv\lib\site-packages\nbclient\client.py", line 1314, in execute
    return NotebookClient(nb=nb, resources=resources, km=km, **kwargs).execute()
  File "d:\github projects\reflectorch\reflectorch\.venv\lib\site-packages\jupyter_core\utils\__init__.py", line 165, in wrapped
    return loop.run_until_complete(inner)
  File "C:\Users\valen\AppData\Local\Programs\Python\Python39\lib\asyncio\base_events.py", line 642, in run_until_complete
    return future.result()
  File "d:\github projects\reflectorch\reflectorch\.venv\lib\site-packages\nbclient\client.py", line 709, in async_execute
    await self.async_execute_cell(
  File "d:\github projects\reflectorch\reflectorch\.venv\lib\site-packages\nbclient\client.py", line 1062, in async_execute_cell
    await self._check_raise_for_error(cell, cell_index, exec_reply)
  File "d:\github projects\reflectorch\reflectorch\.venv\lib\site-packages\nbclient\client.py", line 918, in _check_raise_for_error
    raise CellExecutionError.from_cell_and_msg(cell, exec_reply_content)
nbclient.exceptions.CellExecutionError: An error occurred while executing the following cell:
------------------
trainer = get_trainer_by_name(config_name=trained_model_name, load_weights=True)
------------------

----- stdout -----
Model c1_trained loaded. Number of parameters: 3.83 M
------------------

[1;31m---------------------------------------------------------------------------[0m
[1;31mFileNotFoundError[0m                         Traceback (most recent call last)
File [1;32mD:\Github Projects\reflectorch\reflectorch\reflectorch\runs\utils.py:211[0m, in [0;36mget_trainer_by_name[1;34m(config_name, config_dir, model_path, load_weights)[0m
[0;32m    210[0m [38;5;28;01mtry[39;00m:
[1;32m--> 211[0m     state_dict [38;5;241m=[39m [43mtorch[49m[38;5;241;43m.[39;49m[43mload[49m[43m([49m[43mmodel_path[49m[43m)[49m
[0;32m    212[0m [38;5;28;01mexcept[39;00m [38;5;167;01mException[39;00m [38;5;28;01mas[39;00m err:

File [1;32md:\github projects\reflectorch\reflectorch\.venv\lib\site-packages\torch\serialization.py:998[0m, in [0;36mload[1;34m(f, map_location, pickle_module, weights_only, mmap, **pickle_load_args)[0m
[0;32m    996[0m     pickle_load_args[[38;5;124m'[39m[38;5;124mencoding[39m[38;5;124m'[39m] [38;5;241m=[39m [38;5;124m'[39m[38;5;124mutf-8[39m[38;5;124m'[39m
[1;32m--> 998[0m [38;5;28;01mwith[39;00m [43m_open_file_like[49m[43m([49m[43mf[49m[43m,[49m[43m [49m[38;5;124;43m'[39;49m[38;5;124;43mrb[39;49m[38;5;124;43m'[39;49m[43m)[49m [38;5;28;01mas[39;00m opened_file:
[0;32m    999[0m     [38;5;28;01mif[39;00m _is_zipfile(opened_file):
[0;32m   1000[0m         [38;5;66;03m# The zipfile reader is going to advance the current file position.[39;00m
[0;32m   1001[0m         [38;5;66;03m# If we want to actually tail call to torch.jit.load, we need to[39;00m
[0;32m   1002[0m         [38;5;66;03m# reset back to the original position.[39;00m

File [1;32md:\github projects\reflectorch\reflectorch\.venv\lib\site-packages\torch\serialization.py:445[0m, in [0;36m_open_file_like[1;34m(name_or_buffer, mode)[0m
[0;32m    444[0m [38;5;28;01mif[39;00m _is_path(name_or_buffer):
[1;32m--> 445[0m     [38;5;28;01mreturn[39;00m [43m_open_file[49m[43m([49m[43mname_or_buffer[49m[43m,[49m[43m [49m[43mmode[49m[43m)[49m
[0;32m    446[0m [38;5;28;01melse[39;00m:

File [1;32md:\github projects\reflectorch\reflectorch\.venv\lib\site-packages\torch\serialization.py:426[0m, in [0;36m_open_file.__init__[1;34m(self, name, mode)[0m
[0;32m    425[0m [38;5;28;01mdef[39;00m [38;5;21m__init__[39m([38;5;28mself[39m, name, mode):
[1;32m--> 426[0m     [38;5;28msuper[39m()[38;5;241m.[39m[38;5;21m__init__[39m([38;5;28;43mopen[39;49m[43m([49m[43mname[49m[43m,[49m[43m [49m[43mmode[49m[43m)[49m)

[1;31mFileNotFoundError[0m: [Errno 2] No such file or directory: 'D:\\Github Projects\\reflectorch\\reflectorch\\saved_models\\model_c1_trained.pt'

The above exception was the direct cause of the following exception:

[1;31mRuntimeError[0m                              Traceback (most recent call last)
Cell [1;32mIn[3], line 1[0m
[1;32m----> 1[0m trainer [38;5;241m=[39m [43mget_trainer_by_name[49m[43m([49m[43mconfig_name[49m[38;5;241;43m=[39;49m[43mtrained_model_name[49m[43m,[49m[43m [49m[43mload_weights[49m[38;5;241;43m=[39;49m[38;5;28;43;01mTrue[39;49;00m[43m)[49m

File [1;32mD:\Github Projects\reflectorch\reflectorch\reflectorch\runs\utils.py:213[0m, in [0;36mget_trainer_by_name[1;34m(config_name, config_dir, model_path, load_weights)[0m
[0;32m    211[0m     state_dict [38;5;241m=[39m torch[38;5;241m.[39mload(model_path)
[0;32m    212[0m [38;5;28;01mexcept[39;00m [38;5;167;01mException[39;00m [38;5;28;01mas[39;00m err:
[1;32m--> 213[0m     [38;5;28;01mraise[39;00m [38;5;167;01mRuntimeError[39;00m([38;5;124mf[39m[38;5;124m'[39m[38;5;124mCould not load model from [39m[38;5;132;01m{[39;00mmodel_path[38;5;132;01m}[39;00m[38;5;124m'[39m) [38;5;28;01mfrom[39;00m [38;5;21;01merr[39;00m
[0;32m    215[0m [38;5;28;01mif[39;00m [38;5;124m'[39m[38;5;124mmodel[39m[38;5;124m'[39m [38;5;129;01min[39;00m state_dict:
[0;32m    216[0m     trainer[38;5;241m.[39mmodel[38;5;241m.[39mload_state_dict(state_dict[[38;5;124m'[39m[38;5;124mmodel[39m[38;5;124m'[39m])

[1;31mRuntimeError[0m: Could not load model from D:\Github Projects\reflectorch\reflectorch\saved_models\model_c1_trained.pt

